2024-07-18 11:10:47,542 ERROR test_env Imports failed!
Traceback (most recent call last):
  File "C:\Users\Liezl\Projects\py310_pyside6_qtpy\envexp\test_env.py", line 136, in test_imports
    raise Exception(error)
Exception: Not a conda environment: C:\Users\Liezl\miniconda3\envs\experiment

EnvironmentLocationNotFound: Not a conda environment: C:\Users\Liezl\miniconda3\envs\experiment


